<?xml version="1.0"?>
<robot xmlns:sensor="http://playerstage.sourceforge.net/gazebo/xmlschema/#sensor"
       xmlns:controller="http://playerstage.sourceforge.net/gazebo/xmlschema/#controller"
       xmlns:interface="http://playerstage.sourceforge.net/gazebo/xmlschema/#interface"
       xmlns:xacro="http://ros.org/wiki/xacro">
       
  <xacro:include filename="$(find mir_description)/urdf/motors/dynamixel_motor_ax-12a.gazebo.xacro" />
  <xacro:include filename="$(find mir_description)/urdf/motors/dynamixel_motor_ax-12a.transmission.xacro" />

  <xacro:macro name="dynamixel_motor_AX-12A" params="parent name *origin motor_direction position_offset">

    <joint name="${name}_base_joint" type="fixed" >
      <xacro:insert_block name="origin" />
      <parent link="${parent}" />
      <child link="${name}_base_link" />
    </joint>

    <link name="${name}_base_link">
      <inertial>
        <origin xyz="0 0 0" rpy="0 0 0"/>
        <mass value="0.054"/>
        <inertia ixx="0.01" ixy="0" ixz="0" iyy="0.01" iyz="0" izz="0.01" />
      </inertial>
      
      <visual>
        <origin xyz="0 0 0.03" rpy="0 ${M_PI/2} 0" />
        <geometry>
          <mesh filename="file://$(find mir_description)/meshes/motors/dynamixel_motor_ax-12a.dae" scale="0.001 0.001 0.001" />
        </geometry>
      </visual>

      <collision>
        <origin xyz="0 0 0.03" rpy="0 ${M_PI/2} 0" />
        <geometry>
          <mesh filename="file://$(find mir_description)/meshes/motors/dynamixel_motor_ax-12a_convex_hull.dae" scale="0.001 0.001 0.001" />
        </geometry>
      </collision>
    </link>
    
    <joint name="${name}_joint" type="revolute" >
      <parent link="${name}_base_link" />
      <child link="${name}_link" />
      <origin xyz="0 0 0.03" rpy="${position_offset} 0 ${M_PI}"/>
      <axis xyz="${motor_direction} 0 0"/>
      <dynamics damping="1.0" friction="1.0" />
      <limit effort="1.5" lower="-${M_PI / 180 * 150}" upper="${M_PI / 180 * 150}" velocity="6.178465545"/>
    </joint>

    <link name="${name}_link">
      <inertial>
        <origin xyz="0 0 0" rpy="0 0 0"/>
        <mass value="0.001"/>
        <inertia ixx="0.01" ixy="0" ixz="0" iyy="0.01" iyz="0" izz="0.01" />
      </inertial>
    </link>
    
    <!-- extensions -->
	<xacro:dynamixel_motor_AX-12A_gazebo name="${name}" />
	<xacro:dynamixel_motor_AX-12A_transmission name="${name}" />

  </xacro:macro>

</robot>
