<?xml version="1.0"?>
<robot xmlns:xacro="http://ros.org/wiki/xacro">

	<xacro:include filename="$(find mir_description)/urdf/ptu/ptu46.gazebo.xacro" />
	<xacro:include filename="$(find mir_description)/urdf/ptu/ptu46.transmission.xacro" />

	<xacro:macro name="ptu46" params="parent name *origin">
		<link name="${name}_link">
			<inertial>
				<mass value="1" />
				<origin xyz="0 0 0" />
				<inertia ixx="0.1" ixy="0" ixz="0" iyy="0.1" iyz="0" izz="0.1" />
			</inertial>
			
			<visual>
				<geometry>
					<box size="0.09 0.07 0.055"/>
				</geometry>
				<origin xyz="-0.01 0 0" rpy="0 0 0" />
				<material name="Blue" />
			</visual>
			
			<collision>
				<origin xyz="0 0 0" rpy="0 0 0" />
				<geometry>
					<box size="0.09 0.07 0.055"/>
				</geometry>
			</collision>
		</link>
		
		<joint name="${name}_joint" type="fixed">
			<xacro:insert_block name="origin" />
			<parent link="${parent}"/>
			<child link="${name}_link"/>
		</joint>
	
		<link name="${name}_pan_link">
			<inertial>
				<mass value="1" />
				<origin xyz="0 0 0" />
				<inertia ixx="0.1" ixy="0" ixz="0" iyy="0.1" iyz="0" izz="0.1" />
			</inertial>
			
			<visual>
				<origin xyz="-0.0275 0 0" rpy="0 0 0" />
				<geometry>
					<box size="0.09 0.042 0.065"/>
				</geometry>
				<origin xyz="0 0 0" rpy="0 0 0" />
				<material name="Red" />
			</visual>
			
			<collision>
				<origin xyz="-0.0275 0 0" rpy="0 0 0" />
				<geometry>
					<box size="0.09 0.042 0.065"/>
				</geometry>
			</collision>
		</link>
	
		<joint name="${name}_pan_joint" type="revolute">
			<parent link="${name}_link"/>
			<child link="${name}_pan_link"/>
			<axis xyz="0 0 1"/>
			<origin xyz="0.0175 0 0.06" rpy="0 0 0" />
			<calibration rising="${ptu_pan_ref}"/>
			<dynamics damping="25.0" friction="10.0"/>
			<limit effort="100" lower="-2.8551527828676626" upper="2.8551527828676626" velocity="3.6978386527625844"/>
		</joint>
	
	
		<link name="${name}_tilt_link">
			<inertial>
				<mass value="1" />
				<origin xyz="0 0 0" />
				<inertia ixx="0.1" ixy="0" ixz="0" iyy="0.1" iyz="0" izz="0.1" />
			</inertial>
			
			<visual>
				<origin xyz="0 0 0.02" rpy="0 0 0" />
				<geometry>
					<box size="0.025 0.064 0.05"/>
				</geometry>
				<origin xyz="0 0 0" rpy="0 0 0" />
				<material name="Blue" />
			</visual>
			
			<collision>
				<origin xyz="0 0 0.02" rpy="0 0 0" />
				<geometry>
					<box size="0.025 0.064 0.05"/>
				</geometry>
			</collision>
		</link>
	
		<joint name="${name}_tilt_joint" type="revolute">
			<parent link="${name}_pan_link"/>
			<child link="${name}_tilt_link"/>
			<axis xyz="0 1 0"/>
			<origin xyz="0 0 0.0017" rpy="0 0 ${M_PI}" />
			<calibration rising="${ptu_tilt_ref}"/>
			<dynamics damping="25.0" friction="10.0"/>
			<limit effort="100" lower="-0.83806588157312945" upper="0.55809458927251399" velocity="3.6978386527625844"/>
		</joint>

		<!-- extensions -->
		<xacro:ptu46_gazebo name="${name}" />
		<xacro:ptu46_transmission name="${name}" />
	</xacro:macro>

</robot>
